Exception in thread Thread-2:
Traceback (most recent call last):
  File "/usr/lib/python2.7/threading.py", line 552, in __bootstrap_inner
    self.run()
  File "/usr/lib/python2.7/threading.py", line 505, in run
    self.__target(*self.__args, **self.__kwargs)
  File "/home/pi/beer_fridge/command_server.py", line 35, in acceptConnections
    conn, addr = self.sock.accept()
  File "/usr/lib/python2.7/socket.py", line 202, in accept
    sock, addr = self._sock.accept()
error: [Errno 22] Invalid argument

Fri Mar  6 02:04:29 2015 Activating HOT current temp: 97.8116
Unexpected error: <type 'exceptions.KeyboardInterrupt'>
Traceback (most recent call last):
  File "./gibson.py", line 182, in <module>
    time.sleep(2)
KeyboardInterrupt
Fri Mar  6 02:04:30 2015 Telling the sock to shutdown!
Fri Mar  6 02:04:30 2015 Telling the sock to shutdown!
Traceback (most recent call last):
  File "./gibson.py", line 199, in <module>
    commandServer.shutdown()
  File "/home/pi/beer_fridge/command_server.py", line 53, in shutdown
    self.sock.shutdown(socket.SHUT_RDWR)
  File "/usr/lib/python2.7/socket.py", line 224, in meth
    return getattr(self._sock,name)(*args)
  File "/usr/lib/python2.7/socket.py", line 170, in _dummy
    raise error(EBADF, 'Bad file descriptor')
socket.error: [Errno 9] Bad file descriptor
